<?xml version="1.0" ?>
<!-- =================================================================================== -->
<!-- |    This document was autogenerated by xacro from robot.urdf.xacro               | -->
<!-- |    EDITING THIS FILE BY HAND IS NOT RECOMMENDED                                 | -->
<!-- =================================================================================== -->
<robot name="robot1">

  <!-- Specify some standard inertial calculations https://en.wikipedia.org/wiki/List_of_moments_of_inertia -->
  <!-- These make use of xacro's mathematical functionality -->
  <joint name="robot1/laser_joint" type="fixed">
    <parent link="robot1/base_link"/>
    <child link="robot1/lidar_link"/>
    <origin rpy="0 0 0" xyz="0.087 0 0.075"/>
  </joint>
  <link name="robot1/lidar_link">
    <visual>
      <geometry>
        <cylinder length="0.03" radius="0.03"/>
      </geometry>
      <material name="red"/>
    </visual>
    <collision>
      <geometry>
        <cylinder length="0.03" radius="0.03"/>
      </geometry>
    </collision>
    <inertial>
      <origin rpy="0 0 0" xyz="0 0 0"/>
      <mass value="0.1"/>
      <inertia ixx="7.583333333333335e-05" ixy="0.0" ixz="0.0" iyy="7.583333333333335e-05" iyz="0.0" izz="0.00012500000000000003"/>
    </inertial>
  </link>
  <gazebo reference="robot1/lidar_link">
    <material>Gazebo/Red</material>
    <sensor name="lidar" type="ray">
      <pose> 0 0 0 0 0 0 </pose>
      <always_on>true</always_on>
      <visualize>true</visualize>
      <update_rate>5</update_rate>
      <ray>
        <scan>
          <horizontal>
            <samples>360</samples>
            <min_angle>-3.14</min_angle>
            <max_angle>3.14</max_angle>
            <!-- min_angle>0.000000</min_angle>
                        <max_angle>6.280000</max_angle -->
          </horizontal>
        </scan>
        <range>
          <min>0.4</min>
          <max>12</max>
          <resolution>0.015000</resolution>
        </range>
        <noise>
          <type>gaussian</type>
          <mean>0.0</mean>
          <stddev>0.01</stddev>
        </noise>
      </ray>
      <plugin filename="libgazebo_ros_ray_sensor.so" name="scan">
        <ros>
          <!-- No remap as name is already "scan", plus I added extra space between dashes -->
          <!-- argument>- -ros-args - -remap ~/out:=scan</argument -->
          <remapping>~/out:=/robot1/scan</remapping>
          <namespace>/robot1/lidar</namespace>
        </ros>
        <!-- output_type is LaserScan vs old PointCloud and not a topic -->
        <output_type>sensor_msgs/LaserScan</output_type>
        <frame_name>robot1/lidar_link</frame_name>
      </plugin>
    </sensor>
  </gazebo>
  <joint name="robot1/camera_joint" type="fixed">
    <parent link="robot1/base_link"/>
    <child link="robot1/camera_link"/>
    <origin rpy="0 0 0" xyz="0.15 0 0.03"/>
  </joint>
  <link name="robot1/camera_link">
    <visual>
      <geometry>
        <box size="0.010 0.03 0.03"/>
      </geometry>
      <material name="red"/>
    </visual>
  </link>
  <joint name="robot1/camera_optical_joint" type="fixed">
    <origin rpy="-1.5707963267948966 0 -1.5707963267948966" xyz="0 0 0"/>
    <parent link="robot1/camera_link"/>
    <child link="robot1/camera_link_optical"/>
  </joint>
  <link name="robot1/camera_link_optical"/>
  <gazebo reference="robot1/camera_link">
    <material>Gazebo/Red</material>
    <sensor name="camera" type="camera">
      <pose> 0 0 0 0 0 0 </pose>
      <visualize>true</visualize>
      <update_rate>10</update_rate>
      <camera>
        <horizontal_fov>1.089</horizontal_fov>
        <image>
          <format>R8G8B8</format>
          <width>640</width>
          <height>480</height>
        </image>
        <clip>
          <near>0.05</near>
          <far>8.0</far>
        </clip>
      </camera>
      <plugin filename="libgazebo_ros_camera.so" name="camera_controller">
        <ros>
          <!-- namespace>$(arg namespace)/camera</namespace -->
          <qos>
            <topic name="/robot1/image_raw">
              <publisher>
                <reliability>reliable</reliability>
              </publisher>
            </topic>
          </qos>
        </ros>
        <frame_name>robot1/camera_link_optical</frame_name>
      </plugin>
    </sensor>
  </gazebo>
  <link name="robot1/imu_link">
    <visual>
      <geometry>
        <box size="0.1 0.1 0.1"/>
      </geometry>
    </visual>
    <collision>
      <geometry>
        <box size="0.1 0.1 0.1"/>
      </geometry>
    </collision>
    <inertial>
      <origin rpy="0 0 0" xyz="0 0 0"/>
      <mass value="0.0"/>
      <inertia ixx="0.0" ixy="0.0" ixz="0.0" iyy="0.0" iyz="0.0" izz="0.0"/>
    </inertial>
  </link>
  <joint name="robot1/imu_joint" type="fixed">
    <parent link="robot1/base_link"/>
    <child link="robot1/imu_link"/>
    <origin rpy="0 0 0" xyz="0. 0. 0.02"/>
  </joint>
  <gazebo reference="robot1/imu_link">
    <sensor name="imu_sensor" type="imu">
      <plugin filename="libgazebo_ros_imu_sensor.so" name="imu_plugin">
        <ros>
          <namespace>/robot1/imu</namespace>
          <remapping>~/out:=/robot1/imu</remapping>
        </ros>
        <initial_orientation_as_reference>false</initial_orientation_as_reference>
        <frame_name>imu_link</frame_name>
      </plugin>
      <always_on>true</always_on>
      <update_rate>100</update_rate>
      <visualize>true</visualize>
      <imu>
        <angular_velocity>
          <x>
            <noise type="gaussian">
              <mean>0.0</mean>
              <stddev>2e-4</stddev>
              <bias_mean>0.0000075</bias_mean>
              <bias_stddev>0.0000008</bias_stddev>
            </noise>
          </x>
          <y>
            <noise type="gaussian">
              <mean>0.0</mean>
              <stddev>2e-4</stddev>
              <bias_mean>0.0000075</bias_mean>
              <bias_stddev>0.0000008</bias_stddev>
            </noise>
          </y>
          <z>
            <noise type="gaussian">
              <mean>0.0</mean>
              <stddev>2e-4</stddev>
              <bias_mean>0.0000075</bias_mean>
              <bias_stddev>0.0000008</bias_stddev>
            </noise>
          </z>
        </angular_velocity>
        <linear_acceleration>
          <x>
            <noise type="gaussian">
              <mean>0.0</mean>
              <stddev>1.7e-2</stddev>
              <bias_mean>0.1</bias_mean>
              <bias_stddev>0.001</bias_stddev>
            </noise>
          </x>
          <y>
            <noise type="gaussian">
              <mean>0.0</mean>
              <stddev>1.7e-2</stddev>
              <bias_mean>0.1</bias_mean>
              <bias_stddev>0.001</bias_stddev>
            </noise>
          </y>
          <z>
            <noise type="gaussian">
              <mean>0.0</mean>
              <stddev>1.7e-2</stddev>
              <bias_mean>0.1</bias_mean>
              <bias_stddev>0.001</bias_stddev>
            </noise>
          </z>
        </linear_acceleration>
      </imu>
    </sensor>
  </gazebo>
  <!-- xacro:include filename="$(find multi_robot)/description/xacro/depth_camera.xacro" / -->
  <gazebo>
    <plugin filename="libgazebo_ros_diff_drive.so" name="diff_drive">
      <!-- wheels -->
      <num_wheel_pairs>2</num_wheel_pairs>
      <left_joint>robot1/base_link_left_wheel_frontside</left_joint>
      <left_joint>robot1/base_link_left_wheel_backside</left_joint>
      <right_joint>robot1/base_link_right_wheel_frontside</right_joint>
      <right_joint>robot1/base_link_right_wheel_backside</right_joint>
      <!-- kinematics -->
      <wheel_separation>0.25</wheel_separation>
      <wheel_diameter>0.1</wheel_diameter>
      <!-- Limits -->
      <max_wheel_torque>20.0</max_wheel_torque>
      <max_wheel_acceleration>1.0</max_wheel_acceleration>
      <!-- Output -->
      <!-- odometry_source>world</odometry_source -->
      <!-- Odometry source, 0 for ENCODER, 1 for WORLD, defaults to WORLD -->
      <odometry_source>1</odometry_source>
      <!-- odometry_topic>$(arg namespace)/odom</odometry_topic -->
      <odometry_frame>robot1/odom</odometry_frame>
      <robot_base_frame>robot1/base_link</robot_base_frame>
      <!-- topic & re remappings -->
      <ros>
        <remapping>/cmd_vel:=/robot1/cmd_vel</remapping>
        <remapping>/odom:=/robot1/odom</remapping>
        <namespace>/robot1</namespace>
        <remapping>/tf:=/robot1/tf</remapping>
        <remapping>/tf_static:=/robot1/tf_static</remapping>
      </ros>
      <!-- Receive velocity commands on this ROS topic -->
      <!-- command_topic>cmd_vel</command_topic -->
      <!-- Change the ROS topic we will publish the odometry data to -->
      <!-- ros>
                <remapping>odom:=wheel/odometry</remapping>
            </ros -->
      <publish_odom>true</publish_odom>
      <publish_odom_tf>true</publish_odom_tf>
      <publish_wheel_tf>true</publish_wheel_tf>
      <update_rate>30</update_rate>
    </plugin>
    <!-- plugin name="basic_mobile_bot_joint_state" filename="libgazebo_ros_joint_state_publisher.so">
            <ros>
                <remapping>~/out:=joint_states</remapping>
            </ros>
            <update_rate>30</update_rate>

            <num_wheel_pairs>2</num_wheel_pairs>
            <left_joint>base_link_left_wheel_frontside</left_joint>
            <left_joint>base_link_left_wheel_backside</left_joint>
            <right_joint>base_link_right_wheel_frontside</right_joint>
            <right_joint>base_link_right_wheel_backside</right_joint>
        </plugin -->
  </gazebo>
  <material name="white">
    <color rgba="1 1 1 1"/>
  </material>
  <material name="orange">
    <color rgba="1 0.3 0.1 1"/>
  </material>
  <material name="blue">
    <color rgba="0.2 0.2 1 1"/>
  </material>
  <material name="black">
    <color rgba="0 0 0 1"/>
  </material>
  <material name="red">
    <color rgba="1 0 0 1"/>
  </material>
  <!-- xacro:macro name="static_joint" params="name parent child">
        <joint name="${name}" type="continuous">
            <parent link="${parent}" />
            <child link="${child}" />
            <origin xyz="0 0 0" rpy="0 0 0"/>
        </joint>
    </xacro:macro -->
  <!-- Robot Description -->
  <!-- link name="base_footprint"/ -->
  <link name="robot1/base_link">
    <visual>
      <geometry>
        <box size="0.3 0.2 0.12"/>
        <!-- origin xyz="0.0 0.0"/ -->
      </geometry>
      <material name="Green">
        <color rgba="0 1 0 1"/>
      </material>
    </visual>
    <collision>
      <origin rpy="0 0 0" xyz="0.05 0.055 0.025"/>
      <geometry>
        <box size="0.3 0.2 0.12"/>
      </geometry>
    </collision>
    <inertial>
      <origin rpy="0 0 0" xyz="0.1 0.11 0.05"/>
      <mass value="0.3"/>
      <inertia ixx="0.000365" ixy="0.0" ixz="0.0" iyy="0.00031250000000000006" iyz="0.0" izz="0.0005525"/>
    </inertial>
  </link>
  <link name="robot1/base_footprint">
    <visual>
      <geometry>
        <box size="0.0 0.0 0.0"/>
        <!-- origin xyz="0.0 0.0"/ -->
      </geometry>
      <material name="green">
        <color rgba="0 1 0 1"/>
      </material>
    </visual>
    <collision>
      <origin rpy="0 0 0" xyz="0.0 0.0 0.0"/>
      <geometry>
        <box size="0.0 0.0 0.0"/>
      </geometry>
    </collision>
    <inertial>
      <origin rpy="0 0 0" xyz="0.0 0.0 0.0"/>
      <mass value="0.0"/>
      <inertia ixx="0.0" ixy="0.0" ixz="0.0" iyy="0.0" iyz="0.0" izz="0.0"/>
    </inertial>
  </link>
  <!-- joint name="base_joint" type="fixed">
        <parent link="base_footprint"/>
        <child link="base_link"/>
        <origin xyz="0.0 0.0 ${(wheel_radius+wheel_zoff)}" rpy="0 0 0"/>
        <pose>0 0 0 0 0 0</pose>
    </joint -->
  <joint name="robot1/base_joint" type="fixed">
    <parent link="robot1/base_link"/>
    <child link="robot1/base_footprint"/>
    <origin rpy="0 0 0" xyz="0.0 0.0 -0.125"/>
  </joint>
  <link name="robot1/right_wheel_frontside">
    <visual>
      <geometry>
        <cylinder length="0.05" radius="0.075"/>
      </geometry>
      <material name="wheel_red">
        <color rgba="1 0 0 1"/>
      </material>
    </visual>
    <collision>
      <geometry>
        <cylinder length="0.05" radius="0.075"/>
        /&gt;
                
      </geometry>
      <material name="blue"/>
    </collision>
    <inertial>
      <origin rpy="0 0 0" xyz="0 0 0"/>
      <mass value="0.1"/>
      <inertia ixx="0.0001614583333333333" ixy="0.0" ixz="0.0" iyy="0.0001614583333333333" iyz="0.0" izz="0.00028125"/>
    </inertial>
  </link>
  <joint name="robot1/base_link_right_wheel_frontside" type="continuous">
    <parent link="robot1/base_link"/>
    <child link="robot1/right_wheel_frontside"/>
    <origin rpy="-1.5707963267948966 0 0" xyz="0.09999999999999999 -0.125 -0.05"/>
    <axis rpy="0 0 0" xyz="0 0 1"/>
    <!-- limit effort="1" velocity="1"/>
            <joint_properties damping="1.0" friction="1.0"/ -->
  </joint>
  <link name="robot1/right_wheel_backside">
    <visual>
      <geometry>
        <cylinder length="0.05" radius="0.075"/>
      </geometry>
      <material name="wheel_red">
        <color rgba="1 0 0 1"/>
      </material>
    </visual>
    <collision>
      <geometry>
        <cylinder length="0.05" radius="0.075"/>
        /&gt;
                
      </geometry>
      <material name="blue"/>
    </collision>
    <inertial>
      <origin rpy="0 0 0" xyz="0 0 0"/>
      <mass value="0.1"/>
      <inertia ixx="0.0001614583333333333" ixy="0.0" ixz="0.0" iyy="0.0001614583333333333" iyz="0.0" izz="0.00028125"/>
    </inertial>
  </link>
  <joint name="robot1/base_link_right_wheel_backside" type="continuous">
    <parent link="robot1/base_link"/>
    <child link="robot1/right_wheel_backside"/>
    <origin rpy="-1.5707963267948966 0 0" xyz="-0.09999999999999999 -0.125 -0.05"/>
    <axis rpy="0 0 0" xyz="0 0 1"/>
    <!-- limit effort="1" velocity="1"/>
            <joint_properties damping="1.0" friction="1.0"/ -->
  </joint>
  <link name="robot1/left_wheel_frontside">
    <visual>
      <geometry>
        <cylinder length="0.05" radius="0.075"/>
      </geometry>
      <material name="wheel_red">
        <color rgba="1 0 0 1"/>
      </material>
    </visual>
    <collision>
      <geometry>
        <cylinder length="0.05" radius="0.075"/>
        /&gt;
                
      </geometry>
      <material name="blue"/>
    </collision>
    <inertial>
      <origin rpy="0 0 0" xyz="0 0 0"/>
      <mass value="0.1"/>
      <inertia ixx="0.0001614583333333333" ixy="0.0" ixz="0.0" iyy="0.0001614583333333333" iyz="0.0" izz="0.00028125"/>
    </inertial>
  </link>
  <joint name="robot1/base_link_left_wheel_frontside" type="continuous">
    <parent link="robot1/base_link"/>
    <child link="robot1/left_wheel_frontside"/>
    <origin rpy="-1.5707963267948966 0 0" xyz="0.09999999999999999 0.125 -0.05"/>
    <axis rpy="0 0 0" xyz="0 0 1"/>
    <!-- limit effort="1" velocity="1"/>
            <joint_properties damping="1.0" friction="1.0"/ -->
  </joint>
  <link name="robot1/left_wheel_backside">
    <visual>
      <geometry>
        <cylinder length="0.05" radius="0.075"/>
      </geometry>
      <material name="wheel_red">
        <color rgba="1 0 0 1"/>
      </material>
    </visual>
    <collision>
      <geometry>
        <cylinder length="0.05" radius="0.075"/>
        /&gt;
                
      </geometry>
      <material name="blue"/>
    </collision>
    <inertial>
      <origin rpy="0 0 0" xyz="0 0 0"/>
      <mass value="0.1"/>
      <inertia ixx="0.0001614583333333333" ixy="0.0" ixz="0.0" iyy="0.0001614583333333333" iyz="0.0" izz="0.00028125"/>
    </inertial>
  </link>
  <joint name="robot1/base_link_left_wheel_backside" type="continuous">
    <parent link="robot1/base_link"/>
    <child link="robot1/left_wheel_backside"/>
    <origin rpy="-1.5707963267948966 0 0" xyz="-0.09999999999999999 0.125 -0.05"/>
    <axis rpy="0 0 0" xyz="0 0 1"/>
    <!-- limit effort="1" velocity="1"/>
            <joint_properties damping="1.0" friction="1.0"/ -->
  </joint>
  <!-- Gazebo Colors -->
  <gazebo reference="robot1/base_link">
    <material>Gazebo/Green</material>
  </gazebo>
  <gazebo reference="robot1/right_wheel_frontside">
    <material>Gazebo/Red</material>
  </gazebo>
  <gazebo reference="robot1/right_wheel_backside">
    <material>Gazebo/Red</material>
  </gazebo>
  <gazebo reference="robot1/left_wheel_frontside">
    <material>Gazebo/Red</material>
  </gazebo>
  <gazebo reference="robot1/left_wheel_backside">
    <material>Gazebo/Red</material>
  </gazebo>
</robot>
