<?xml version="1.0" ?>
<!-- =================================================================================== -->
<!-- |    This document was autogenerated by xacro from my_robot.urdf.xacro            | -->
<!-- |    EDITING THIS FILE BY HAND IS NOT RECOMMENDED                                 | -->
<!-- =================================================================================== -->
<robot name="my_robot">
  <material name="green">
    <color rgba="0 1 0 1"/>
  </material>
  <material name="blue">
    <color rgba="0 0 1 1"/>
  </material>
  <material name="red">
    <color rgba="1 0 0 1"/>
  </material>
  <material name="grey">
    <color rgba="0.5 0.5 0.5 1"/>
  </material>
  <link name="base_footprint">
    </link>
  <link name="base_link">
    <visual>
      <geometry>
        <box size="0.3 0.2 0.11"/>
      </geometry>
      <origin rpy="0 0 0" xyz="0 0 0.055"/>
      <material name="blue"/>
    </visual>
    <collision>
      <geometry>
        <box size="0.3 0.2 0.11"/>
      </geometry>
      <origin rpy="0 0 0" xyz="0 0 0.055"/>
    </collision>
    <inertial>
      <origin rpy="0 0 0" xyz="0 0 0.055"/>
      <mass value="5.0"/>
      <inertia ixx="0.17016666666666666" ixy="0" ixz="0" iyy="0.21666666666666667" iyz="0" izz="0.08683333333333335"/>
    </inertial>
  </link>
  <link name="right_wheel_link">
    <visual>
      <geometry>
        <cylinder length="0.05" radius="0.09"/>
      </geometry>
      <origin rpy="1.5707963267948966 0 0" xyz="0 0 0"/>
      <material name="grey"/>
    </visual>
    <collision>
      <geometry>
        <cylinder length="0.05" radius="0.09"/>
      </geometry>
      <origin rpy="1.5707963267948966 0 0" xyz="0 0 0"/>
    </collision>
    <inertial>
      <origin rpy="1.5707963267948966 0 0" xyz="0 0 0"/>
      <mass value="1.0"/>
      <inertia ixx="0.008933333333333335" ixy="0" ixz="0" iyy="0.008933333333333335" iyz="0" izz="0.0162"/>
    </inertial>
  </link>
  <link name="left_wheel_link">
    <visual>
      <geometry>
        <cylinder length="0.05" radius="0.09"/>
      </geometry>
      <origin rpy="1.5707963267948966 0 0" xyz="0 0 0"/>
      <material name="grey"/>
    </visual>
    <collision>
      <geometry>
        <cylinder length="0.05" radius="0.09"/>
      </geometry>
      <origin rpy="1.5707963267948966 0 0" xyz="0 0 0"/>
    </collision>
    <inertial>
      <origin rpy="1.5707963267948966 0 0" xyz="0 0 0"/>
      <mass value="1.0"/>
      <inertia ixx="0.008933333333333335" ixy="0" ixz="0" iyy="0.008933333333333335" iyz="0" izz="0.0162"/>
    </inertial>
  </link>
  <link name="caster_wheel_link">
    <visual>
      <geometry>
        <sphere radius="0.045"/>
      </geometry>
      <origin rpy="0 0 0" xyz="0 0 0"/>
      <material name="grey"/>
    </visual>
    <collision>
      <geometry>
        <sphere radius="0.045"/>
      </geometry>
      <origin rpy="0 0 0" xyz="0 0 0"/>
    </collision>
    <inertial>
      <origin rpy="0 0 0" xyz="0 0 0"/>
      <mass value="0.5"/>
      <inertia ixx="0.00162" ixy="0" ixz="0" iyy="0.00162" iyz="0" izz="0.00162"/>
    </inertial>
  </link>
  <joint name="base_joint" type="fixed">
    <parent link="base_footprint"/>
    <child link="base_link"/>
    <origin rpy="0 0 0" xyz=" 0.0 0.0 0.09"/>
  </joint>
  <joint name="base_right_wheel_joint" type="continuous">
    <parent link="base_link"/>
    <child link="right_wheel_link"/>
    <origin rpy="0 0 0" xyz="-0.075 -0.125 0"/>
    <axis xyz="0 1 0"/>
  </joint>
  <joint name="base_left_wheel_joint" type="continuous">
    <parent link="base_link"/>
    <child link="left_wheel_link"/>
    <origin rpy="0 0 0" xyz="-0.075 0.125 0"/>
    <axis xyz="0 1 0"/>
  </joint>
  <joint name="base_caster_wheel_joint" type="fixed">
    <parent link="base_link"/>
    <child link="caster_wheel_link"/>
    <origin rpy="0 0 0" xyz="0.09999999999999999 0 -0.045"/>
    <axis xyz="0 1 0"/>
  </joint>
  <gazebo reference="base_link">
    <material>Gazebo/Blue</material>
  </gazebo>
  <gazebo reference="right_wheel_link">
    <material>Gazebo/Grey</material>
  </gazebo>
  <gazebo reference="left_wheel_link">
    <material>Gazebo/Grey</material>
  </gazebo>
  <gazebo reference="caster_wheel_link">
    <material>Gazebo/Grey</material>
    <mu1 value="0.1"/>
    <mu2 value="0.1"/>
  </gazebo>
  <gazebo>
    <plugin filename="libgazebo_ros_diff_drive.so" name="diff_drive_controller">
      <!-- Update rate in Hz -->
      <ros>
        <!-- <namespace>/robot0</namespace> -->
        <remapping>/tf:=tf</remapping>
      </ros>
      <update_rate>30</update_rate>
      <!-- wheels -->
      <left_joint>base_left_wheel_joint</left_joint>
      <right_joint>base_right_wheel_joint</right_joint>
      <!-- kinematics -->
      <wheel_separation>0.45</wheel_separation>
      <wheel_diameter>0.2</wheel_diameter>
      <!-- output -->
      <publish_odom>true</publish_odom>
      <publish_odom_tf>true</publish_odom_tf>
      <publish_wheel_tf>false</publish_wheel_tf>
      <odometry_topic>odom</odometry_topic>
      <odometry_frame>odom</odometry_frame>
      <robot_base_frame>base_footprint</robot_base_frame>
    </plugin>

    <plugin name="turtlebot3_joint_state" filename="libgazebo_ros_joint_state_publisher.so">
      <ros>
        <!-- <namespace>/tb3</namespace> -->
        <remapping>~/out:=joint_states</remapping>
      </ros>
      <update_rate>30</update_rate>
      <joint_name>base_left_wheel_joint</joint_name>
      <joint_name>base_right_wheel_joint</joint_name>
    </plugin>  
  </gazebo>
  <link name="camera_link">
    <visual>
      <geometry>
        <!-- l b h IN METER-->
        <box size="0.01 0.1 0.05"/>
      </geometry>
      <material name="grey"/>
    </visual>
    <collision>
      <geometry>
        <!-- l b h IN METER-->
        <box size="0.01 0.2 0.05"/>
      </geometry>
    </collision>
    <inertial>
      <origin rpy="0 0 0" xyz="0 0 0"/>
      <mass value="0.1"/>
      <inertia ixx="2.166666666666667e-05" ixy="0" ixz="0" iyy="8.416666666666668e-05" iyz="0" izz="0.00010416666666666669"/>
    </inertial>
  </link>
  <joint name="base_camera_joint" type="fixed">
    <parent link="base_link"/>
    <child link="camera_link"/>
    <origin rpy="0 0 0" xyz="0.155 0.0 0.055"/>
  </joint>
  <!-- gazebo camera link -->
  <gazebo reference="camera_link">
    <material>Gazebo/Red</material>
    <sensor name="camera_sensor" type="camera">
      <pose>0 0 0 0 0 0</pose>
      <visualize>true</visualize>
      <update_rate>10.0</update_rate>
      <camera name="head">
        <horizontal_fov>1.3962634</horizontal_fov>
        <image>
          <width>800</width>
          <height>800</height>
          <format>R8G8B8</format>
        </image>
        <clip>
          <near>0.02</near>
          <far>300</far>
        </clip>
        <noise>
          <type>gaussian</type>
          <!-- Noise is sampled independently per pixel on each frame.
                        That pixel's noise value is added to each of its color
                        channels, which at that point lie in the range [0,1]. -->
          <mean>0.0</mean>
          <stddev>0.007</stddev>
        </noise>
      </camera>
      <plugin filename="libgazebo_ros_camera.so" name="camera_driver">
        <alwaysOn>true</alwaysOn>
        <updateRate>0.0</updateRate>
        <cameraName>camera_sensor</cameraName>
        <imageTopicName>image_raw</imageTopicName>
        <cameraInfoTopicName>camera_info</cameraInfoTopicName>
        <frameName>camera_link</frameName>
        <hackBaseline>0.07</hackBaseline>
        <distortionK1>0.0</distortionK1>
        <distortionK2>0.0</distortionK2>
        <distortionK3>0.0</distortionK3>
        <distortionT1>0.0</distortionT1>
        <distortionT2>0.0</distortionT2>
      </plugin>
    </sensor>
  </gazebo>
  <!-- LiDAR Link -->
  <link name="base_scan">
    <visual>
      <geometry>
        <cylinder length="0.05" radius="0.02"/>
      </geometry>
      <material name="red"/>
    </visual>
    <collision>
      <geometry>
        <cylinder length="0.05" radius="0.02"/>
      </geometry>
    </collision>
    <inertial>
      <mass value="0.114"/>
      <origin rpy="0 0 0" xyz="0 0 0.025"/>
      <inertia ixx="0.001" ixy="0.0" ixz="0.0" iyy="0.001" iyz="0.0" izz="0.001"/>
    </inertial>
  </link>
  <!-- LiDAR Joint -->
  <joint name="base_lidar_joint" type="fixed">
    <parent link="base_link"/>
    <child link="base_scan"/>
    <origin rpy="0 0 0" xyz="0.09999999999999999 0.0 0.135"/>
  </joint>
  <!-- Gazebo LiDAR sensor -->
  <gazebo reference="base_scan">
    <material>Gazebo/Red</material>
    <sensor name="lidar_sensor" type="ray">
      <pose>0 0 0 0 0 0</pose>
      <visualize>true</visualize>
      <update_rate>10.0</update_rate>
      <ray>
        <scan>
          <horizontal>
            <samples>360</samples>
            <!-- Number of laser points -->
            <min_angle>-3.14</min_angle>
            <!-- -90 degrees -->
            <max_angle>3.14</max_angle>
            <!-- 90 degrees -->
          </horizontal>
        </scan>
        <range>
          <min>0.12</min>
          <!-- Minimum range of the LiDAR -->
          <max>10</max>
          <resolution>0.015000</resolution>
          <!-- Maximum range of the LiDAR -->
        </range>
      </ray>
      <plugin filename="libgazebo_ros_ray_sensor.so" name="laserscan">
        <ros>
          <remapping>~/out:=scan</remapping>
        </ros>
        <output_type>sensor_msgs/LaserScan</output_type>
        <alwaysOn>true</alwaysOn>
        <update_rate>10.0</update_rate>
        <!-- Ensure it's 10Hz -->
        <!-- <topicName>scan</topicName> -->
        <frameName>base_scan</frameName>
      </plugin>
    </sensor>
  </gazebo>

  

  <link name="imu_link"/>
  <joint name="imu_joint" type="fixed">
    <parent link="base_link"/>
    <child link="imu_link"/>
    <origin rpy="0 0 0" xyz="0.0 0 0.068"/>
  </joint>
  <gazebo reference="imu_link">
    <sensor name="imu" type="imu">
      <always_on>true</always_on>
      <visualize>true</visualize>
      <!-- Set to true for visualization -->
      <update_rate>200</update_rate>
      <!-- Added update rate here -->
      <pose>0 0 0 0 0 0</pose>
      <!-- Added pose -->
    </sensor>
    <material>Gazebo/Red</material>
    <plugin filename="libgazebo_ros_imu_sensor.so" name="my_imu_plugin">
      <ros>
        <!-- <namespace>/imu</namespace> -->
        <remapping>~/out:=imu</remapping>
      </ros>
      <alwaysOn>true</alwaysOn>
      <bodyName>imu_link</bodyName>
      <frameName>imu_link</frameName>
      <topicName>imu</topicName>
      <output_type>sensor_msgs/Imu</output_type>
      <gaussianNoise>0.0</gaussianNoise>
      <update_rate>10.0</update_rate>
      <imu>
        <noise>
          <type>gaussian</type>
          <rate>
            <mean>0.0</mean>
            <stddev>2e-4</stddev>
            <bias_mean>0.0000075</bias_mean>
            <bias_stddev>0.0000008</bias_stddev>
          </rate>
          <accel>
            <mean>0.0</mean>
            <stddev>1.7e-2</stddev>
            <bias_mean>0.1</bias_mean>
            <bias_stddev>0.001</bias_stddev>
          </accel>
        </noise>
      </imu>
    </plugin>
    
  </gazebo>
</robot>
